<?xml version="1.0" ?>
<!-- =================================================================================== -->
<!-- |    This document was autogenerated by xacro from franka_ros/franka_description/robots/panda/panda.urdf.xacro | -->
<!-- |    EDITING THIS FILE BY HAND IS NOT RECOMMENDED                                 | -->
<!-- =================================================================================== -->
<robot name="panda_nohand" xmlns:xacro="http://www.ros.org/wiki/xacro">
    <material name="white">
        <color rgba="1 1 1 1"/>
    </material>
    <material name="off_white">
        <color rgba="0.901961 0.921569 0.929412 1"/>
    </material>
    <material name="dark_grey">
        <color rgba="0.25 0.25 0.25 1"/>
    </material>
    <material name="green">
        <color rgba="0 1 0 1"/>
    </material>
    <material name="light_blue">
        <color rgba="0.039216 0.541176 0.780392 1"/>
    </material>

    <link name="panda_link0_0">
        <visual>
            <geometry>
                <mesh filename="package://assets/link0_0.obj" />
            </geometry>
            <material name="off_white"/>
        </visual>
        <collision>
            <geometry>
                <mesh filename="package://assets/link0.stl" />
            </geometry>
        </collision>
        <inertial>
            <origin rpy="0 0 0" xyz="-0.041018 -0.00014 0.049974"/>
            <mass value="0.629769"/>
            <inertia ixx="0.00315" ixy="8.2904e-07" ixz="0.00015" iyy="0.00388" iyz="8.2299e-06" izz="0.004285"/>
        </inertial>
    </link>
    <link name="panda_link0_1">
        <visual>
            <geometry>
                <mesh filename="package://assets/link0_1.obj" />
            </geometry>
            <material name="dark_grey"/>
        </visual>
        <inertial>
            <origin rpy="0 0 0" xyz="0 0 0"/>
            <mass value="0"/>
            <inertia ixx="0" ixy="0" ixz="0" iyy="0" iyz="0" izz="0"/>
        </inertial>
    </link>
    <link name="panda_link0_2">
        <visual>
            <geometry>
                <mesh filename="package://assets/link0_2.obj" />
            </geometry>
            <material name="off_white"/>
        </visual>
        <inertial>
            <origin rpy="0 0 0" xyz="0 0 0"/>
            <mass value="0"/>
            <inertia ixx="0" ixy="0" ixz="0" iyy="0" iyz="0" izz="0"/>
        </inertial>
    </link>
    <link name="panda_link0_3">
        <visual>
            <geometry>
                <mesh filename="package://assets/link0_3.obj" />
            </geometry>
            <material name="dark_grey"/>
        </visual>
        <inertial>
            <origin rpy="0 0 0" xyz="0 0 0"/>
            <mass value="0"/>
            <inertia ixx="0" ixy="0" ixz="0" iyy="0" iyz="0" izz="0"/>
        </inertial>
    </link>
    <link name="panda_link0_4">
        <visual>
            <geometry>
                <mesh filename="package://assets/link0_4.obj" />
            </geometry>
            <material name="off_white"/>
        </visual>
        <inertial>
            <origin rpy="0 0 0" xyz="0 0 0"/>
            <mass value="0"/>
            <inertia ixx="0" ixy="0" ixz="0" iyy="0" iyz="0" izz="0"/>
        </inertial>
    </link>
    <link name="panda_link0_5">
        <visual>
            <geometry>
                <mesh filename="package://assets/link0_5.obj" />
            </geometry>
            <material name="dark_grey"/>
        </visual>
        <inertial>
            <origin rpy="0 0 0" xyz="0 0 0"/>
            <mass value="0"/>
            <inertia ixx="0" ixy="0" ixz="0" iyy="0" iyz="0" izz="0"/>
        </inertial>
    </link>
    <link name="panda_link0_7">
        <visual>
            <geometry>
                <mesh filename="package://assets/link0_7.obj" />
            </geometry>
            <material name="white"/>
        </visual>
        <inertial>
            <origin rpy="0 0 0" xyz="0 0 0"/>
            <mass value="0"/>
            <inertia ixx="0" ixy="0" ixz="0" iyy="0" iyz="0" izz="0"/>
        </inertial>
    </link>
    <link name="panda_link0_8">
        <visual>
            <geometry>
                <mesh filename="package://assets/link0_8.obj" />
            </geometry>
            <material name="white"/>
        </visual>
        <inertial>
            <origin rpy="0 0 0" xyz="0 0 0"/>
            <mass value="0"/>
            <inertia ixx="0" ixy="0" ixz="0" iyy="0" iyz="0" izz="0"/>
        </inertial>
    </link>
    <link name="panda_link0_9">
        <visual>
            <geometry>
                <mesh filename="package://assets/link0_9.obj" />
            </geometry>
            <material name="dark_grey"/>
        </visual>
        <inertial>
            <origin rpy="0 0 0" xyz="0 0 0"/>
            <mass value="0"/>
            <inertia ixx="0" ixy="0" ixz="0" iyy="0" iyz="0" izz="0"/>
        </inertial>
    </link>
    <link name="panda_link0_10">
        <visual>
            <geometry>
                <mesh filename="package://assets/link0_10.obj" />
            </geometry>
            <material name="off_white"/>
        </visual>
        <inertial>
            <origin rpy="0 0 0" xyz="0 0 0"/>
            <mass value="0"/>
            <inertia ixx="0" ixy="0" ixz="0" iyy="0" iyz="0" izz="0"/>
        </inertial>
    </link>
    <link name="panda_link0_11">
        <visual>
            <geometry>
                <mesh filename="package://assets/link0_11.obj" />
            </geometry>
            <material name="white"/>
        </visual>
        <inertial>
            <origin rpy="0 0 0" xyz="0 0 0"/>
            <mass value="0"/>
            <inertia ixx="0" ixy="0" ixz="0" iyy="0" iyz="0" izz="0"/>
        </inertial>
    </link>

    <link name="panda_link1_0">
        <visual>
            <geometry>
                <mesh filename="package://assets/link1.obj" />
            </geometry>
            <material name="white"/>
        </visual>
        <collision>
            <geometry>
                <mesh filename="package://assets/link1.stl" />
            </geometry>
        </collision>
        <inertial>
            <origin rpy="0 0 0" xyz="0.003875 0.002081 -0.04762"/>
            <mass value="4.970684"/>
            <inertia ixx="0.70337" ixy="-0.000139" ixz="0.006772" iyy="0.70661" iyz="0.019169" izz="0.009117"/>
        </inertial>
    </link>

    <link name="panda_link2_0">
        <visual>
            <geometry>
                <mesh filename="package://assets/link2.obj" />
            </geometry>
            <material name="white"/>
        </visual>
        <collision>
            <geometry>
                <mesh filename="package://assets/link2.stl" />
            </geometry>
        </collision>
        <inertial>
            <origin rpy="0 0 0" xyz="-0.003141 -0.02872  0.003495"/>
            <mass value="0.646926"/>
            <inertia ixx="0.007962" ixy="-0.003925" ixz="0.010254" iyy="0.02811" iyz="0.000704" izz="0.025995"/>
        </inertial>
    </link>

    <link name="panda_link3_0">
        <visual>
            <geometry>
                <mesh filename="package://assets/link3_0.obj" />
            </geometry>
            <material name="white"/>
        </visual>
        <collision>
            <geometry>
                <mesh filename="package://assets/link3.stl" />
            </geometry>
        </collision>
        <inertial>
            <origin rpy="0 0 0" xyz="2.7518e-02 3.9252e-02 -6.6502e-02"/>
            <mass value="3.228604"/>
            <inertia ixx="0.037242" ixy="-0.004761" ixz="-0.011396" iyy="0.036155" iyz="-0.012805" izz="0.01083"/>
        </inertial>
    </link>
    <link name="panda_link3_1">
        <visual>
            <geometry>
                <mesh filename="package://assets/link3_1.obj" />
            </geometry>
            <material name="white"/>
        </visual>
        <inertial>
            <origin rpy="0 0 0" xyz="0 0 0"/>
            <mass value="0"/>
            <inertia ixx="0" ixy="0" ixz="0" iyy="0" iyz="0" izz="0"/>
        </inertial>
    </link>
    <link name="panda_link3_2">
        <visual>
            <geometry>
                <mesh filename="package://assets/link3_2.obj" />
            </geometry>
            <material name="white"/>
        </visual>
        <inertial>
            <origin rpy="0 0 0" xyz="0 0 0"/>
            <mass value="0"/>
            <inertia ixx="0" ixy="0" ixz="0" iyy="0" iyz="0" izz="0"/>
        </inertial>
    </link>
    <link name="panda_link3_3">
        <visual>
            <geometry>
                <mesh filename="package://assets/link3_3.obj" />
            </geometry>
            <material name="dark_grey"/>
        </visual>
        <inertial>
            <origin rpy="0 0 0" xyz="0 0 0"/>
            <mass value="0"/>
            <inertia ixx="0" ixy="0" ixz="0" iyy="0" iyz="0" izz="0"/>
        </inertial>
    </link>

    <link name="panda_link4_0">
        <visual>
            <geometry>
                <mesh filename="package://assets/link4_0.obj" />
            </geometry>
            <material name="white"/>
        </visual>
        <collision>
            <geometry>
                <mesh filename="package://assets/link4.stl" />
            </geometry>
        </collision>
        <inertial>
            <origin rpy="0 0 0" xyz="-5.317e-02 1.04419e-01 2.7454e-02"/>
            <mass value="3.587895"/>
            <inertia ixx="0.025853" ixy="0.007796" ixz="-0.001332" iyy="0.019552" iyz="0.008641" izz="0.028323"/>
        </inertial>
    </link>
    <link name="panda_link4_1">
        <visual>
            <geometry>
                <mesh filename="package://assets/link4_1.obj" />
            </geometry>
            <material name="white"/>
        </visual>
        <inertial>
            <origin rpy="0 0 0" xyz="0 0 0"/>
            <mass value="0"/>
            <inertia ixx="0" ixy="0" ixz="0" iyy="0" iyz="0" izz="0"/>
        </inertial>
    </link>
    <link name="panda_link4_2">
        <visual>
            <geometry>
                <mesh filename="package://assets/link4_2.obj" />
            </geometry>
            <material name="dark_grey"/>
        </visual>
        <inertial>
            <origin rpy="0 0 0" xyz="0 0 0"/>
            <mass value="0"/>
            <inertia ixx="0" ixy="0" ixz="0" iyy="0" iyz="0" izz="0"/>
        </inertial>
    </link>
    <link name="panda_link4_3">
        <visual>
            <geometry>
                <mesh filename="package://assets/link4_3.obj" />
            </geometry>
            <material name="gray"/>
        </visual>
        <inertial>
            <origin rpy="0 0 0" xyz="0 0 0"/>
            <mass value="0"/>
            <inertia ixx="0" ixy="0" ixz="0" iyy="0" iyz="0" izz="0"/>
        </inertial>
    </link>

    <link name="panda_link5_0">
        <visual>
            <geometry>
                <mesh filename="package://assets/link5_0.obj" />
            </geometry>
            <material name="dark_grey"/>
        </visual>
        <collision>
            <geometry>
                <mesh filename="package://assets/link5_collision_0.obj" />
            </geometry>
        </collision>
        <collision>
            <geometry>
                <mesh filename="package://assets/link5_collision_1.obj" />
            </geometry>
        </collision>
        <collision>
            <geometry>
                <mesh filename="package://assets/link5_collision_2.obj" />
            </geometry>
        </collision>
        <inertial>
            <origin rpy="0 0 0" xyz="-1.1953e-02 4.1065e-02 -3.8437e-02"/>
            <mass value="1.225946"/>
            <inertia ixx="0.035549" ixy="-0.002117" ixz="-0.004037" iyy="0.029474" iyz="0.000229" izz="0.008627"/>
        </inertial>
    </link>
    <link name="panda_link5_1">
        <visual>
            <geometry>
                <mesh filename="package://assets/link5_1.obj" />
            </geometry>
            <material name="white"/>
        </visual>
        <inertial>
            <origin rpy="0 0 0" xyz="0 0 0"/>
            <mass value="0"/>
            <inertia ixx="0" ixy="0" ixz="0" iyy="0" iyz="0" izz="0"/>
        </inertial>
    </link>
    <link name="panda_link5_2">
        <visual>
            <geometry>
                <mesh filename="package://assets/link5_2.obj" />
            </geometry>
            <material name="white"/>
        </visual>
        <inertial>
            <origin rpy="0 0 0" xyz="0 0 0"/>
            <mass value="0"/>
            <inertia ixx="0" ixy="0" ixz="0" iyy="0" iyz="0" izz="0"/>
        </inertial>
    </link>

    <link name="panda_link6_0">
        <visual>
            <geometry>
                <mesh filename="package://assets/link6_0.obj" />
            </geometry>
            <material name="off_white"/>
        </visual>
        <collision>
            <geometry>
                <mesh filename="package://assets/link6.stl" />
            </geometry>
        </collision>
        <inertial>
            <origin rpy="0 0 0" xyz="6.0149e-02 -1.4117e-02 -1.0517e-02"/>
            <mass value="1.666555"/>
            <inertia ixx="0.001964" ixy="0.000109" ixz="-0.001158" iyy="0.004354" iyz="0.000341" izz="0.005433"/>
        </inertial>
    </link>
    <link name="panda_link6_1">
        <visual>
            <geometry>
                <mesh filename="package://assets/link6_1.obj" />
            </geometry>
            <material name="white"/>
        </visual>
        <inertial>
            <origin rpy="0 0 0" xyz="0 0 0"/>
            <mass value="0"/>
            <inertia ixx="0" ixy="0" ixz="0" iyy="0" iyz="0" izz="0"/>
        </inertial>
    </link>
    <link name="panda_link6_2">
        <visual>
            <geometry>
                <mesh filename="package://assets/link6_2.obj" />
            </geometry>
            <material name="dark_grey"/>
        </visual>
        <inertial>
            <origin rpy="0 0 0" xyz="0 0 0"/>
            <mass value="0"/>
            <inertia ixx="0" ixy="0" ixz="0" iyy="0" iyz="0" izz="0"/>
        </inertial>
    </link>
    <link name="panda_link6_3">
        <visual>
            <geometry>
                <mesh filename="package://assets/link6_3.obj" />
            </geometry>
            <material name="white"/>
        </visual>
        <inertial>
            <origin rpy="0 0 0" xyz="0 0 0"/>
            <mass value="0"/>
            <inertia ixx="0" ixy="0" ixz="0" iyy="0" iyz="0" izz="0"/>
        </inertial>
    </link>
    <link name="panda_link6_4">
        <visual>
            <geometry>
                <mesh filename="package://assets/link6_4.obj" />
            </geometry>
            <material name="white"/>
        </visual>
        <inertial>
            <origin rpy="0 0 0" xyz="0 0 0"/>
            <mass value="0"/>
            <inertia ixx="0" ixy="0" ixz="0" iyy="0" iyz="0" izz="0"/>
        </inertial>
    </link>
    <link name="panda_link6_5">
        <visual>
            <geometry>
                <mesh filename="package://assets/link6_5.obj" />
            </geometry>
            <material name="white"/>
        </visual>
        <inertial>
            <origin rpy="0 0 0" xyz="0 0 0"/>
            <mass value="0"/>
            <inertia ixx="0" ixy="0" ixz="0" iyy="0" iyz="0" izz="0"/>
        </inertial>
    </link>
    <link name="panda_link6_6">
        <visual>
            <geometry>
                <mesh filename="package://assets/link6_6.obj" />
            </geometry>
            <material name="white"/>
        </visual>
        <inertial>
            <origin rpy="0 0 0" xyz="0 0 0"/>
            <mass value="0"/>
            <inertia ixx="0" ixy="0" ixz="0" iyy="0" iyz="0" izz="0"/>
        </inertial>
    </link>
    <link name="panda_link6_7">
        <visual>
            <geometry>
                <mesh filename="package://assets/link6_7.obj" />
            </geometry>
            <material name="light_blue"/>
        </visual>
        <inertial>
            <origin rpy="0 0 0" xyz="0 0 0"/>
            <mass value="0"/>
            <inertia ixx="0" ixy="0" ixz="0" iyy="0" iyz="0" izz="0"/>
        </inertial>
    </link>
    <link name="panda_link6_8">
        <visual>
            <geometry>
                <mesh filename="package://assets/link6_8.obj" />
            </geometry>
            <material name="light_blue"/>
        </visual>
        <inertial>
            <origin rpy="0 0 0" xyz="0 0 0"/>
            <mass value="0"/>
            <inertia ixx="0" ixy="0" ixz="0" iyy="0" iyz="0" izz="0"/>
        </inertial>
    </link>
    <link name="panda_link6_9">
        <visual>
            <geometry>
                <mesh filename="package://assets/link6_9.obj" />
            </geometry>
            <material name="dark_grey"/>
        </visual>
        <inertial>
            <origin rpy="0 0 0" xyz="0 0 0"/>
            <mass value="0"/>
            <inertia ixx="0" ixy="0" ixz="0" iyy="0" iyz="0" izz="0"/>
        </inertial>
    </link>
    <link name="panda_link6_10">
        <visual>
            <geometry>
                <mesh filename="package://assets/link6_10.obj" />
            </geometry>
            <material name="dark_grey"/>
        </visual>
        <inertial>
            <origin rpy="0 0 0" xyz="0 0 0"/>
            <mass value="0"/>
            <inertia ixx="0" ixy="0" ixz="0" iyy="0" iyz="0" izz="0"/>
        </inertial>
    </link>
    <link name="panda_link6_11">
        <visual>
            <geometry>
                <mesh filename="package://assets/link6_11.obj" />
            </geometry>
            <material name="white"/>
        </visual>
        <inertial>
            <origin rpy="0 0 0" xyz="0 0 0"/>
            <mass value="0"/>
            <inertia ixx="0" ixy="0" ixz="0" iyy="0" iyz="0" izz="0"/>
        </inertial>
    </link>
    <link name="panda_link6_12">
        <visual>
            <geometry>
                <mesh filename="package://assets/link6_12.obj" />
            </geometry>
            <material name="green"/>
        </visual>
        <inertial>
            <origin rpy="0 0 0" xyz="0 0 0"/>
            <mass value="0"/>
            <inertia ixx="0" ixy="0" ixz="0" iyy="0" iyz="0" izz="0"/>
        </inertial>
    </link>
    <link name="panda_link6_13">
        <visual>
            <geometry>
                <mesh filename="package://assets/link6_13.obj" />
            </geometry>
            <material name="white"/>
        </visual>
        <inertial>
            <origin rpy="0 0 0" xyz="0 0 0"/>
            <mass value="0"/>
            <inertia ixx="0" ixy="0" ixz="0" iyy="0" iyz="0" izz="0"/>
        </inertial>
    </link>
    <link name="panda_link6_14">
        <visual>
            <geometry>
                <mesh filename="package://assets/link6_14.obj" />
            </geometry>
            <material name="dark_grey"/>
        </visual>
        <inertial>
            <origin rpy="0 0 0" xyz="0 0 0"/>
            <mass value="0"/>
            <inertia ixx="0" ixy="0" ixz="0" iyy="0" iyz="0" izz="0"/>
        </inertial>
    </link>
    <link name="panda_link6_15">
        <visual>
            <geometry>
                <mesh filename="package://assets/link6_15.obj" />
            </geometry>
            <material name="dark_grey"/>
        </visual>
        <inertial>
            <origin rpy="0 0 0" xyz="0 0 0"/>
            <mass value="0"/>
            <inertia ixx="0" ixy="0" ixz="0" iyy="0" iyz="0" izz="0"/>
        </inertial>
    </link>
    <link name="panda_link6_16">
        <visual>
            <geometry>
                <mesh filename="package://assets/link6_16.obj" />
            </geometry>
            <material name="white"/>
        </visual>
        <inertial>
            <origin rpy="0 0 0" xyz="0 0 0"/>
            <mass value="0"/>
            <inertia ixx="0" ixy="0" ixz="0" iyy="0" iyz="0" izz="0"/>
        </inertial>
    </link>

    <link name="panda_link7_0">
        <visual>
            <geometry>
                <mesh filename="package://assets/link7_0.obj" />
            </geometry>
            <material name="white"/>
        </visual>
        <collision>
            <geometry>
                <mesh filename="package://assets/link7.stl" />
            </geometry>
        </collision>
        <inertial>
            <origin rpy="0 0 0" xyz="1.0517e-02 -4.252e-03 6.1597e-02"/>
            <mass value="0.735522"/>
            <inertia ixx="0.012516" ixy="-0.000428" ixz="-0.001196" iyy="0.010027" iyz="-0.000741" izz="0.004815"/>
        </inertial>
    </link>
    <link name="panda_link7_1">
        <visual>
            <geometry>
                <mesh filename="package://assets/link7_1.obj" />
            </geometry>
            <material name="dark_grey"/>
        </visual>
        <inertial>
            <origin rpy="0 0 0" xyz="0 0 0"/>
            <mass value="0"/>
            <inertia ixx="0" ixy="0" ixz="0" iyy="0" iyz="0" izz="0"/>
        </inertial>
    </link>
    <link name="panda_link7_2">
        <visual>
            <geometry>
                <mesh filename="package://assets/link7_2.obj" />
            </geometry>
            <material name="dark_grey"/>
        </visual>
        <inertial>
            <origin rpy="0 0 0" xyz="0 0 0"/>
            <mass value="0"/>
            <inertia ixx="0" ixy="0" ixz="0" iyy="0" iyz="0" izz="0"/>
        </inertial>
    </link>
    <link name="panda_link7_3">
        <visual>
            <geometry>
                <mesh filename="package://assets/link7_3.obj" />
            </geometry>
            <material name="dark_grey"/>
        </visual>
        <inertial>
            <origin rpy="0 0 0" xyz="0 0 0"/>
            <mass value="0"/>
            <inertia ixx="0" ixy="0" ixz="0" iyy="0" iyz="0" izz="0"/>
        </inertial>
    </link>
    <link name="panda_link7_4">
        <visual>
            <geometry>
                <mesh filename="package://assets/link7_4.obj" />
            </geometry>
            <material name="dark_grey"/>
        </visual>
        <inertial>
            <origin rpy="0 0 0" xyz="0 0 0"/>
            <mass value="0"/>
            <inertia ixx="0" ixy="0" ixz="0" iyy="0" iyz="0" izz="0"/>
        </inertial>
    </link>
    <link name="panda_link7_5">
        <visual>
            <geometry>
                <mesh filename="package://assets/link7_5.obj" />
            </geometry>
            <material name="dark_grey"/>
        </visual>
        <inertial>
            <origin rpy="0 0 0" xyz="0 0 0"/>
            <mass value="0"/>
            <inertia ixx="0" ixy="0" ixz="0" iyy="0" iyz="0" izz="0"/>
        </inertial>
    </link>
    <link name="panda_link7_6">
        <visual>
            <geometry>
                <mesh filename="package://assets/link7_6.obj" />
            </geometry>
            <material name="dark_grey"/>
        </visual>
        <inertial>
            <origin rpy="0 0 0" xyz="0 0 0"/>
            <mass value="0"/>
            <inertia ixx="0" ixy="0" ixz="0" iyy="0" iyz="0" izz="0"/>
        </inertial>
    </link>
    <link name="panda_link7_7">
        <visual>
            <geometry>
                <mesh filename="package://assets/link7_7.obj" />
            </geometry>
            <material name="white"/>
        </visual>
        <inertial>
            <origin rpy="0 0 0" xyz="0 0 0"/>
            <mass value="0"/>
            <inertia ixx="0" ixy="0" ixz="0" iyy="0" iyz="0" izz="0"/>
        </inertial>
    </link>

    <link name="panda_link8_0">
        <inertial>
          <mass value="0"/>
          <origin rpy="0 0 0" xyz="0 0 0"/>
          <inertia ixx="0" ixy="0" ixz="0" iyy="0" iyz="0" izz="0"/>
        </inertial>
    </link>

    <joint name="panda_joint1" type="revolute">
        <origin rpy="0 0 0" xyz="0 0 0.333"/>
        <parent link="panda_link0_0"/>
        <child link="panda_link1_0"/>
        <axis xyz="0 0 1"/>
        <limit effort="87.0" lower="-2.8973" upper="2.8973" velocity="2.175"/>
        <safety_controller k_position="100.0" k_velocity="40.0" soft_lower_limit="-2.8973" soft_upper_limit="2.8973"/>
        <dynamics D="1" K="7000" damping="0.003" friction="0.0" mu_coulomb="0" mu_viscous="16"/>
    </joint>
    <joint name="panda_joint2" type="revolute">
        <origin rpy="-1.5707963267948966 0 0" xyz="0 0 0"/>
        <parent link="panda_link1_0"/>
        <child link="panda_link2_0"/>
        <axis xyz="0 0 1"/>
        <limit effort="87.0" lower="-1.7628" upper="1.7628" velocity="2.175"/>
        <safety_controller k_position="100.0" k_velocity="40.0" soft_lower_limit="-1.7628" soft_upper_limit="1.7628"/>
        <dynamics D="1" K="7000" damping="0.003" friction="0.0" mu_coulomb="0" mu_viscous="16"/>
    </joint>
    <joint name="panda_joint3" type="revolute">
        <origin rpy="1.5707963267948966 0 0" xyz="0 -0.316 0"/>
        <parent link="panda_link2_0"/>
        <child link="panda_link3_0"/>
        <axis xyz="0 0 1"/>
        <limit effort="87.0" lower="-2.8973" upper="2.8973" velocity="2.175"/>
        <safety_controller k_position="100.0" k_velocity="40.0" soft_lower_limit="-2.8973" soft_upper_limit="2.8973"/>
        <dynamics D="1" K="7000" damping="0.003" friction="0.0" mu_coulomb="0" mu_viscous="16"/>
    </joint>
    <joint name="panda_joint4" type="revolute">
        <origin rpy="1.5707963267948966 0 0" xyz="0.0825 0 0"/>
        <parent link="panda_link3_0"/>
        <child link="panda_link4_0"/>
        <axis xyz="0 0 1"/>
        <limit effort="87.0" lower="-3.0718" upper="-0.0698" velocity="2.175"/>
        <safety_controller k_position="100.0" k_velocity="40.0" soft_lower_limit="-3.0718" soft_upper_limit="-0.0698"/>
        <dynamics D="1" K="7000" damping="0.003" friction="0.0" mu_coulomb="0" mu_viscous="16"/>
    </joint>
    <joint name="panda_joint5" type="revolute">
        <origin rpy="-1.5707963267948966 0 0" xyz="-0.0825 0.384 0"/>
        <parent link="panda_link4_0"/>
        <child link="panda_link5_0"/>
        <axis xyz="0 0 1"/>
        <limit effort="12.0" lower="-2.8973" upper="2.8973" velocity="2.61"/>
        <safety_controller k_position="100.0" k_velocity="40.0" soft_lower_limit="-2.8973" soft_upper_limit="2.8973"/>
        <dynamics D="1" K="7000" damping="0.003" friction="0.0" mu_coulomb="0" mu_viscous="16"/>
    </joint>
    <joint name="panda_joint6" type="revolute">
        <origin rpy="1.5707963267948966 0 0" xyz="0 0 0"/>
        <parent link="panda_link5_0"/>
        <child link="panda_link6_0"/>
        <axis xyz="0 0 1"/>
        <limit effort="12.0" lower="-0.0175" upper="3.7525" velocity="2.61"/>
        <safety_controller k_position="100.0" k_velocity="40.0" soft_lower_limit="-0.0175" soft_upper_limit="3.7525"/>
        <dynamics D="1" K="7000" damping="0.003" friction="0.0" mu_coulomb="0" mu_viscous="16"/>
    </joint>
    <joint name="panda_joint7" type="revolute">
        <origin rpy="1.5707963267948966 0 0" xyz="0.088 0 0"/>
        <parent link="panda_link6_0"/>
        <child link="panda_link7_0"/>
        <axis xyz="0 0 1"/>
        <limit effort="12.0" lower="-2.8973" upper="2.8973" velocity="2.61"/>
        <safety_controller k_position="100.0" k_velocity="40.0" soft_lower_limit="-2.8973" soft_upper_limit="2.8973"/>
        <dynamics D="1" K="7000" damping="0.003" friction="0.0" mu_coulomb="0" mu_viscous="16"/>
    </joint>
    <joint name="panda_joint8" type="fixed">
        <origin rpy="0 0 0" xyz="0 0 0.107"/>
        <parent link="panda_link7_0"/>
        <child link="panda_link8_0"/>
    </joint>

    <joint name="panda_link0_1" type="fixed">
        <parent link="panda_link0_0"/>
        <child link="panda_link0_1"/>
        <origin rpy="0 0 0" xyz="0 0 0"/>
    </joint>
    <joint name="panda_link0_2" type="fixed">
        <parent link="panda_link0_0"/>
        <child link="panda_link0_2"/>
        <origin rpy="0 0 0" xyz="0 0 0"/>
    </joint>
    <joint name="panda_link0_3" type="fixed">
        <parent link="panda_link0_0"/>
        <child link="panda_link0_3"/>
        <origin rpy="0 0 0" xyz="0 0 0"/>
    </joint>
    <joint name="panda_link0_4" type="fixed">
        <parent link="panda_link0_0"/>
        <child link="panda_link0_4"/>
        <origin rpy="0 0 0" xyz="0 0 0"/>
    </joint>
    <joint name="panda_link0_5" type="fixed">
        <parent link="panda_link0_0"/>
        <child link="panda_link0_5"/>
        <origin rpy="0 0 0" xyz="0 0 0"/>
    </joint>
    <joint name="panda_link0_7" type="fixed">
        <parent link="panda_link0_0"/>
        <child link="panda_link0_7"/>
        <origin rpy="0 0 0" xyz="0 0 0"/>
    </joint>
    <joint name="panda_link0_8" type="fixed">
        <parent link="panda_link0_0"/>
        <child link="panda_link0_8"/>
        <origin rpy="0 0 0" xyz="0 0 0"/>
    </joint>
    <joint name="panda_link0_9" type="fixed">
        <parent link="panda_link0_0"/>
        <child link="panda_link0_9"/>
        <origin rpy="0 0 0" xyz="0 0 0"/>
    </joint>
    <joint name="panda_link0_10" type="fixed">
        <parent link="panda_link0_0"/>
        <child link="panda_link0_10"/>
        <origin rpy="0 0 0" xyz="0 0 0"/>
    </joint>
    <joint name="panda_link0_11" type="fixed">
        <parent link="panda_link0_0"/>
        <child link="panda_link0_11"/>
        <origin rpy="0 0 0" xyz="0 0 0"/>
    </joint>
    <joint name="panda_link3_1" type="fixed">
        <parent link="panda_link3_0"/>
        <child link="panda_link3_1"/>
        <origin rpy="0 0 0" xyz="0 0 0"/>
    </joint>
    <joint name="panda_link3_2" type="fixed">
        <parent link="panda_link3_0"/>
        <child link="panda_link3_2"/>
        <origin rpy="0 0 0" xyz="0 0 0"/>
    </joint>
    <joint name="panda_link3_3" type="fixed">
        <parent link="panda_link3_0"/>
        <child link="panda_link3_3"/>
        <origin rpy="0 0 0" xyz="0 0 0"/>
    </joint>

    <joint name="panda_link4_1" type="fixed">
        <parent link="panda_link4_0"/>
        <child link="panda_link4_1"/>
        <origin rpy="0 0 0" xyz="0 0 0"/>
    </joint>
    <joint name="panda_link4_2" type="fixed">
        <parent link="panda_link4_0"/>
        <child link="panda_link4_2"/>
        <origin rpy="0 0 0" xyz="0 0 0"/>
    </joint>
    <joint name="panda_link4_3" type="fixed">
        <parent link="panda_link4_0"/>
        <child link="panda_link4_3"/>
        <origin rpy="0 0 0" xyz="0 0 0"/>
    </joint>

    <joint name="panda_link5_1" type="fixed">
        <parent link="panda_link5_0"/>
        <child link="panda_link5_1"/>
        <origin rpy="0 0 0" xyz="0 0 0"/>
    </joint>
    <joint name="panda_link5_2" type="fixed">
        <parent link="panda_link5_0"/>
        <child link="panda_link5_2"/>
        <origin rpy="0 0 0" xyz="0 0 0"/>
    </joint>

    <joint name="panda_link6_1" type="fixed">
        <parent link="panda_link6_0"/>
        <child link="panda_link6_1"/>
        <origin rpy="0 0 0" xyz="0 0 0"/>
    </joint>
    <joint name="panda_link6_2" type="fixed">
        <parent link="panda_link6_0"/>
        <child link="panda_link6_2"/>
        <origin rpy="0 0 0" xyz="0 0 0"/>
    </joint>
    <joint name="panda_link6_3" type="fixed">
        <parent link="panda_link6_0"/>
        <child link="panda_link6_3"/>
        <origin rpy="0 0 0" xyz="0 0 0"/>
    </joint>
    <joint name="panda_link6_4" type="fixed">
        <parent link="panda_link6_0"/>
        <child link="panda_link6_4"/>
        <origin rpy="0 0 0" xyz="0 0 0"/>
    </joint>
    <joint name="panda_link6_5" type="fixed">
        <parent link="panda_link6_0"/>
        <child link="panda_link6_5"/>
        <origin rpy="0 0 0" xyz="0 0 0"/>
    </joint>
    <joint name="panda_link6_6" type="fixed">
        <parent link="panda_link6_0"/>
        <child link="panda_link6_6"/>
        <origin rpy="0 0 0" xyz="0 0 0"/>
    </joint>
    <joint name="panda_link6_7" type="fixed">
        <parent link="panda_link6_0"/>
        <child link="panda_link6_7"/>
        <origin rpy="0 0 0" xyz="0 0 0"/>
    </joint>
    <joint name="panda_link6_8" type="fixed">
        <parent link="panda_link6_0"/>
        <child link="panda_link6_8"/>
        <origin rpy="0 0 0" xyz="0 0 0"/>
    </joint>
    <joint name="panda_link6_9" type="fixed">
        <parent link="panda_link6_0"/>
        <child link="panda_link6_9"/>
        <origin rpy="0 0 0" xyz="0 0 0"/>
    </joint>
    <joint name="panda_link6_10" type="fixed">
        <parent link="panda_link6_0"/>
        <child link="panda_link6_10"/>
        <origin rpy="0 0 0" xyz="0 0 0"/>
    </joint>
    <joint name="panda_link6_11" type="fixed">
        <parent link="panda_link6_0"/>
        <child link="panda_link6_11"/>
        <origin rpy="0 0 0" xyz="0 0 0"/>
    </joint>
    <joint name="panda_link6_12" type="fixed">
        <parent link="panda_link6_0"/>
        <child link="panda_link6_12"/>
        <origin rpy="0 0 0" xyz="0 0 0"/>
    </joint>
    <joint name="panda_link6_13" type="fixed">
        <parent link="panda_link6_0"/>
        <child link="panda_link6_13"/>
        <origin rpy="0 0 0" xyz="0 0 0"/>
    </joint>
    <joint name="panda_link6_14" type="fixed">
        <parent link="panda_link6_0"/>
        <child link="panda_link6_14"/>
        <origin rpy="0 0 0" xyz="0 0 0"/>
    </joint>
    <joint name="panda_link6_15" type="fixed">
        <parent link="panda_link6_0"/>
        <child link="panda_link6_15"/>
        <origin rpy="0 0 0" xyz="0 0 0"/>
    </joint>
    <joint name="panda_link6_16" type="fixed">
        <parent link="panda_link6_0"/>
        <child link="panda_link6_16"/>
        <origin rpy="0 0 0" xyz="0 0 0"/>
    </joint>

    <joint name="panda_link7_1" type="fixed">
        <parent link="panda_link7_0"/>
        <child link="panda_link7_1"/>
        <origin rpy="0 0 0" xyz="0 0 0"/>
    </joint>
    <joint name="panda_link7_2" type="fixed">
        <parent link="panda_link7_0"/>
        <child link="panda_link7_2"/>
        <origin rpy="0 0 0" xyz="0 0 0"/>
    </joint>
    <joint name="panda_link7_3" type="fixed">
        <parent link="panda_link7_0"/>
        <child link="panda_link7_3"/>
        <origin rpy="0 0 0" xyz="0 0 0"/>
    </joint>
    <joint name="panda_link7_4" type="fixed">
        <parent link="panda_link7_0"/>
        <child link="panda_link7_4"/>
        <origin rpy="0 0 0" xyz="0 0 0"/>
    </joint>
    <joint name="panda_link7_5" type="fixed">
        <parent link="panda_link7_0"/>
        <child link="panda_link7_5"/>
        <origin rpy="0 0 0" xyz="0 0 0"/>
    </joint>
    <joint name="panda_link7_6" type="fixed">
        <parent link="panda_link7_0"/>
        <child link="panda_link7_6"/>
        <origin rpy="0 0 0" xyz="0 0 0"/>
    </joint>
    <joint name="panda_link7_7" type="fixed">
        <parent link="panda_link7_0"/>
        <child link="panda_link7_7"/>
        <origin rpy="0 0 0" xyz="0 0 0"/>
    </joint>
</robot>